Workbook
Name LastChange: 'SOW initial'!$I$13
Name USD: 'Costfile - Invoice discussion'!$B$4
Name EUR: 'Costfile - Invoice discussion'!$B$5
Name prevWBS: '3rd party Planner'!$A1048576
Name USD: 'Budget file'!$B$4
Name EUR: 'Budget file'!$B$5

Sheet Costfile - Invoice discussion
A2: PRICE COMPARISON - DRYDOCKING AL-IDRISI | I2: not completed yet | P2: Rev. # | Q2: Name | R2: Date
A3: 1 <CUR> = | C3: Wisselkoers <date> | I3: agreed | P3: =IFERROR(LOOKUP(2,1/('SOW initial'!$G$3:$G$12<>""),'SOW initial'!$G$3:$G$12),"") | Q3: =IFERROR(LOOKUP(2,1/('SOW initial'!$H$3:$H$12<>""),'SOW initial'!$H$3:$H$12),"") | R3: =IFERROR(LOOKUP(2,1/('SOW initial'!$I$3:$I$12<>""),'SOW initial'!$I$3:$I$12),"")
A4: 1 USD = | I4: not agreed | P4: Last change | R4: =LastChange
A5: 1 USD = | I5: discussion
E6: Yard 1 | H6: Draft Invoice | I6: Draft Invoice | J6: %total | L6: Agreed | M6: Discussion | N6: Not agreed | O6: Obtained reduction | P6: Final | Q6: Remarks | R6: Cost Code
A7: Par. | B7: Description | C7: Units | D7: Qty. | E7: USD/unit | F7: USD | G7: Qty. | H7: USD/unit | I7: USD | J7: % | L7: USD | M7: USD | N7: USD | O7: USD | P7: USD
F8: =D8*E8 | I8: =H8*G8 | J8: =IFERROR(I8/$I$104,0) | P8: =I8-O8
F9: =D9*E9 | I9: =H9*G9 | J9: =IFERROR(I9/$I$104,0) | P9: =I9-O9
F10: =D10*E10 | I10: =H10*G10 | J10: =IFERROR(I10/$I$104,0) | P10: =I10-O10
F11: =D11*E11 | I11: =H11*G11 | J11: =IFERROR(I11/$I$104,0) | P11: =I11-O11
F12: =D12*E12 | I12: =H12*G12 | J12: =IFERROR(I12/$I$104,0) | P12: =I12-O12
B13: Subtotal Pilotage, mooring and unmooring | F13: =SUBTOTAL(9,F8:F12) | H13: =SUBTOTAL(9,H8:H12) | I13: =SUBTOTAL(9,I8:I12) | J13: =IFERROR(I13/$I$104,0) | L13: =SUBTOTAL(9,L8:L12) | M13: =SUBTOTAL(9,M8:M12) | N13: =SUBTOTAL(9,N8:N12) | O13: =SUBTOTAL(9,O8:O12) | P13: =SUBTOTAL(9,P8:P12)
F14: =D14*E14 | I14: =H14*G14 | J14: =IFERROR(I14/$I$104,0) | P14: =I14-O14
F15: =D15*E15 | I15: =H15*G15 | J15: =IFERROR(I15/$I$104,0) | P15: =I15-O15
F16: =D16*E16 | I16: =H16*G16 | J16: =IFERROR(I16/$I$104,0) | P16: =I16-O16
F17: =D17*E17 | I17: =H17*G17 | J17: =IFERROR(I17/$I$104,0) | P17: =I17-O17
F18: =D18*E18 | I18: =H18*G18 | J18: =IFERROR(I18/$I$104,0) | P18: =I18-O18
B19: Subtotal Drydocking | F19: =SUBTOTAL(9,F14:F18) | H19: =SUBTOTAL(9,H14:H18) | I19: =SUBTOTAL(9,I14:I18) | J19: =IFERROR(I19/$I$104,0) | L19: =SUBTOTAL(9,L14:L18) | M19: =SUBTOTAL(9,M14:M18) | N19: =SUBTOTAL(9,N14:N18) | O19: =SUBTOTAL(9,O14:O18) | P19: =SUBTOTAL(9,P14:P18)
F20: =D20*E20 | I20: =H20*G20 | J20: =IFERROR(I20/$I$104,0) | P20: =I20-O20
F21: =D21*E21 | I21: =H21*G21 | J21: =IFERROR(I21/$I$104,0) | P21: =I21-O21
F22: =D22*E22 | I22: =H22*G22 | J22: =IFERROR(I22/$I$104,0) | P22: =I22-O22
F23: =D23*E23 | I23: =H23*G23 | J23: =IFERROR(I23/$I$104,0) | P23: =I23-O23
F24: =D24*E24 | I24: =H24*G24 | J24: =IFERROR(I24/$I$104,0) | P24: =I24-O24
B25: Subtotal Services | F25: =SUBTOTAL(9,F20:F24) | H25: =SUBTOTAL(9,H20:H24) | I25: =SUBTOTAL(9,I20:I24) | J25: =IFERROR(I25/$I$104,0) | L25: =SUBTOTAL(9,L20:L24) | M25: =SUBTOTAL(9,M20:M24) | N25: =SUBTOTAL(9,N20:N24) | O25: =SUBTOTAL(9,O20:O24) | P25: =SUBTOTAL(9,P20:P24)
F26: =D26*E26 | I26: =H26*G26 | J26: =IFERROR(I26/$I$104,0) | P26: =I26-O26
F27: =D27*E27 | I27: =H27*G27 | J27: =IFERROR(I27/$I$104,0) | P27: =I27-O27
F28: =D28*E28 | I28: =H28*G28 | J28: =IFERROR(I28/$I$104,0) | P28: =I28-O28
F29: =D29*E29 | I29: =H29*G29 | J29: =IFERROR(I29/$I$104,0) | P29: =I29-O29
F30: =D30*E30 | I30: =H30*G30 | J30: =IFERROR(I30/$I$104,0) | P30: =I30-O30
B31: Subtotal General | F31: =SUBTOTAL(9,F26:F30) | H31: =SUBTOTAL(9,H26:H30) | I31: =SUBTOTAL(9,I26:I30) | J31: =IFERROR(I31/$I$104,0) | L31: =SUBTOTAL(9,L26:L30) | M31: =SUBTOTAL(9,M26:M30) | N31: =SUBTOTAL(9,N26:N30) | O31: =SUBTOTAL(9,O26:O30) | P31: =SUBTOTAL(9,P26:P30)
F32: =D32*E32 | I32: =H32*G32 | J32: =IFERROR(I32/$I$104,0) | P32: =I32-O32
F33: =D33*E33 | I33: =H33*G33 | J33: =IFERROR(I33/$I$104,0) | P33: =I33-O33
F34: =D34*E34 | I34: =H34*G34 | J34: =IFERROR(I34/$I$104,0) | P34: =I34-O34
F35: =D35*E35 | I35: =H35*G35 | J35: =IFERROR(I35/$I$104,0) | P35: =I35-O35
F36: =D36*E36 | I36: =H36*G36 | J36: =IFERROR(I36/$I$104,0) | P36: =I36-O36
B37: Subtotal Surface preparations | F37: =SUBTOTAL(9,F32:F36) | H37: =SUBTOTAL(9,H32:H36) | I37: =SUBTOTAL(9,I32:I36) | J37: =IFERROR(I37/$I$104,0) | L37: =SUBTOTAL(9,L32:L36) | M37: =SUBTOTAL(9,M32:M36) | N37: =SUBTOTAL(9,N32:N36) | O37: =SUBTOTAL(9,O32:O36) | P37: =SUBTOTAL(9,P32:P36)
F38: =D38*E38 | I38: =H38*G38 | J38: =IFERROR(I38/$I$104,0) | P38: =I38-O38
F39: =D39*E39 | I39: =H39*G39 | J39: =IFERROR(I39/$I$104,0) | P39: =I39-O39
F40: =D40*E40 | I40: =H40*G40 | J40: =IFERROR(I40/$I$104,0) | P40: =I40-O40
F41: =D41*E41 | I41: =H41*G41 | J41: =IFERROR(I41/$I$104,0) | P41: =I41-O41
...

Sheet AXI cost breakdown
A1: AL-IDRISI DRYDOCK 2027 - AXI COST BREAKDOWN | M1: Rev. # | N1: Name | O1: Date
M2: =IFERROR(LOOKUP(2,1/('SOW initial'!$G$3:$G$12<>""),'SOW initial'!$G$3:$G$12),"") | N2: =IFERROR(LOOKUP(2,1/('SOW initial'!$H$3:$H$12<>""),'SOW initial'!$H$3:$H$12),"") | O2: =IFERROR(LOOKUP(2,1/('SOW initial'!$I$3:$I$12<>""),'SOW initial'!$I$3:$I$12),"")
M3: Last change | O3: =LastChange
A5: Costplace | B5: Cost Carrier | C5: Detailcode | D5: Detail Description | E5: Comments | F5: Document Curr | G5: Initial Amount Doc curr | H5: Discount Amount Doc curr | I5: Final Amount Doc Curr | J5: Reallocation General costs | K5: Spread % | L5: Final Amount EUR
C6: 447 | E6: General cost shipyard | F6: USD | G6: ='Costfile - Invoice discussion'!O120 | H6: =IFERROR($H$38/$G$38*G6,0) | I6: =IFERROR(G6-H6,0)
E7: Non recoverable taxes and VAT | F7: USD | G7: 0 | H7: =IFERROR($H$38/$G$38*G7,0) | I7: =IFERROR(G7-H7,0)
A8: 80 | B8: 8038 | C8: 303 | D8: W & T Piping | F8: USD | G8: 0 | H8: =IFERROR($H$38/$G$38*G8,0) | I8: =IFERROR(G8-H8,0) | J8: =IFERROR(I8+(($I$6+$I$7)*I8/($I$38-($I$6+$I$7))),0) | K8: =IFERROR(J8/$I$38,0) | L8: =IFERROR($L$38*K8,0)
A9: 80 | B9: 8038 | C9: 304 | D9: W & T Others | F9: USD | G9: 0 | H9: =IFERROR($H$38/$G$38*G9,0) | I9: =IFERROR(G9-H9,0) | J9: =IFERROR(I9+(($I$6+$I$7)*I9/($I$38-($I$6+$I$7))),0) | K9: =IFERROR(J9/$I$38,0) | L9: =IFERROR($L$38*K9,0)
A10: 80 | B10: 8038 | C10: 400 | D10: O&R Main Drives | F10: USD | G10: ='Costfile - Invoice discussion'!O110 | H10: =IFERROR($H$38/$G$38*G10,0) | I10: =IFERROR(G10-H10,0) | J10: =IFERROR(I10+(($I$6+$I$7)*I10/($I$38-($I$6+$I$7))),0) | K10: =IFERROR(J10/$I$38,0) | L10: =IFERROR($L$38*K10,0)
A11: 80 | B11: 8038 | C11: 401 | D11: O&R Auxilliary drives | F11: USD | G11: ='Costfile - Invoice discussion'!O111 | H11: =IFERROR($H$38/$G$38*G11,0) | I11: =IFERROR(G11-H11,0) | J11: =IFERROR(I11+(($I$6+$I$7)*I11/($I$38-($I$6+$I$7))),0) | K11: =IFERROR(J11/$I$38,0) | L11: =IFERROR($L$38*K11,0)
A12: 80 | B12: 8038 | C12: 402 | D12: O&R Electrical | F12: USD | G12: 0 | H12: =IFERROR($H$38/$G$38*G12,0) | I12: =IFERROR(G12-H12,0) | J12: =IFERROR(I12+(($I$6+$I$7)*I12/($I$38-($I$6+$I$7))),0) | K12: =IFERROR(J12/$I$38,0) | L12: =IFERROR($L$38*K12,0)
A13: 80 | B13: 8038 | C13: 403 | D13: O&R Hydraulic | F13: USD | G13: 0 | H13: =IFERROR($H$38/$G$38*G13,0) | I13: =IFERROR(G13-H13,0) | J13: =IFERROR(I13+(($I$6+$I$7)*I13/($I$38-($I$6+$I$7))),0) | K13: =IFERROR(J13/$I$38,0) | L13: =IFERROR($L$38*K13,0)
A14: 80 | B14: 8038 | C14: 404 | D14: O&R Hoisting Equipment | F14: USD | G14: 0 | H14: =IFERROR($H$38/$G$38*G14,0) | I14: =IFERROR(G14-H14,0) | J14: =IFERROR(I14+(($I$6+$I$7)*I14/($I$38-($I$6+$I$7))),0) | K14: =IFERROR(J14/$I$38,0) | L14: =IFERROR($L$38*K14,0)
A15: 80 | B15: 8038 | C15: 405 | D15: O&R Engine Room | F15: USD | G15: ='Costfile - Invoice discussion'!O115 | H15: =IFERROR($H$38/$G$38*G15,0) | I15: =IFERROR(G15-H15,0) | J15: =IFERROR(I15+(($I$6+$I$7)*I15/($I$38-($I$6+$I$7))),0) | K15: =IFERROR(J15/$I$38,0) | L15: =IFERROR($L$38*K15,0)
A16: 80 | B16: 8038 | C16: 406 | D16: O&R Dredging Equipment | F16: USD | G16: 0 | H16: =IFERROR($H$38/$G$38*G16,0) | I16: =IFERROR(G16-H16,0) | J16: =IFERROR(I16+(($I$6+$I$7)*I16/($I$38-($I$6+$I$7))),0) | K16: =IFERROR(J16/$I$38,0) | L16: =IFERROR($L$38*K16,0)
A17: 80 | B17: 8038 | C17: 407 | D17: O&R Hull | F17: USD | G17: ='Costfile - Invoice discussion'!O117 | H17: =IFERROR($H$38/$G$38*G17,0) | I17: =IFERROR(G17-H17,0) | J17: =IFERROR(I17+(($I$6+$I$7)*I17/($I$38-($I$6+$I$7))),0) | K17: =IFERROR(J17/$I$38,0) | L17: =IFERROR($L$38*K17,0)
A18: 80 | B18: 8038 | C18: 408 | D18: O&R Hopper | F18: USD | G18: ='Costfile - Invoice discussion'!O118 | H18: =IFERROR($H$38/$G$38*G18,0) | I18: =IFERROR(G18-H18,0) | J18: =IFERROR(I18+(($I$6+$I$7)*I18/($I$38-($I$6+$I$7))),0) | K18: =IFERROR(J18/$I$38,0) | L18: =IFERROR($L$38*K18,0)
A19: 80 | B19: 8038 | C19: 411 | D19: O&R General | F19: USD | G19: ='Costfile - Invoice discussion'!O119 | H19: =IFERROR($H$38/$G$38*G19,0) | I19: =IFERROR(G19-H19,0) | J19: =IFERROR(I19+(($I$6+$I$7)*I19/($I$38-($I$6+$I$7))),0) | K19: =IFERROR(J19/$I$38,0) | L19: =IFERROR($L$38*K19,0)
A20: 80 | B20: 8038 | C20: 449 | D20: O&R Classification & Inspection | F20: USD | G20: ='Costfile - Invoice discussion'!O121 | H20: =IFERROR($H$38/$G$38*G20,0) | I20: =IFERROR(G20-H20,0) | J20: =IFERROR(I20+(($I$6+$I$7)*I20/($I$38-($I$6+$I$7))),0) | K20: =IFERROR(J20/$I$38,0) | L20: =IFERROR($L$38*K20,0)
A21: 80 | B21: 8038 | C21: 453 | D21: Fuel | F21: USD | G21: ='Costfile - Invoice discussion'!O122 | H21: =IFERROR($H$38/$G$38*G21,0) | I21: =IFERROR(G21-H21,0) | J21: =IFERROR(I21+(($I$6+$I$7)*I21/($I$38-($I$6+$I$7))),0) | K21: =IFERROR(J21/$I$38,0) | L21: =IFERROR($L$38*K21,0)
A22: 80 | B22: 8038 | C22: 463 | D22: Fresh water supplies | F22: USD | G22: ='Costfile - Invoice discussion'!O123 | H22: =IFERROR($H$38/$G$38*G22,0) | I22: =IFERROR(G22-H22,0) | J22: =IFERROR(I22+(($I$6+$I$7)*I22/($I$38-($I$6+$I$7))),0) | K22: =IFERROR(J22/$I$38,0) | L22: =IFERROR($L$38*K22,0)
A23: 80 | B23: 8038 | C23: 464 | D23: Waste disposal & collection | F23: USD | G23: ='Costfile - Invoice discussion'!O124 | H23: =IFERROR($H$38/$G$38*G23,0) | I23: =IFERROR(G23-H23,0) | J23: =IFERROR(I23+(($I$6+$I$7)*I23/($I$38-($I$6+$I$7))),0) | K23: =IFERROR(J23/$I$38,0) | L23: =IFERROR($L$38*K23,0)
A24: 80 | B24: 8038 | C24: 484 | D24: Shore power supply | F24: USD | G24: ='Costfile - Invoice discussion'!O125 | H24: =IFERROR($H$38/$G$38*G24,0) | I24: =IFERROR(G24-H24,0) | J24: =IFERROR(I24+(($I$6+$I$7)*I24/($I$38-($I$6+$I$7))),0) | K24: =IFERROR(J24/$I$38,0) | L24: =IFERROR($L$38*K24,0)
D25: Automatische creatie | G25: 0 | H25: =IFERROR($H$38/$G$38*G25,0) | I25: =IFERROR(G25-H25,0) | J25: =IFERROR(I25+(($I$6+$I$7)*I25/($I$38-($I$6+$I$7))),0) | K25: =IFERROR(J25/$I$38,0) | L25: =IFERROR($L$38*K25,0)
D26: Automatische creatie | G26: 0 | H26: =IFERROR($H$38/$G$38*G26,0) | I26: =IFERROR(G26-H26,0) | J26: =IFERROR(I26+(($I$6+$I$7)*I26/($I$38-($I$6+$I$7))),0) | K26: =IFERROR(J26/$I$38,0) | L26: =IFERROR($L$38*K26,0)
D27: Automatische creatie | G27: 0 | H27: =IFERROR($H$38/$G$38*G27,0) | I27: =IFERROR(G27-H27,0) | J27: =IFERROR(I27+(($I$6+$I$7)*I27/($I$38-($I$6+$I$7))),0) | K27: =IFERROR(J27/$I$38,0) | L27: =IFERROR($L$38*K27,0)
D28: Automatische creatie | G28: 0 | H28: =IFERROR($H$38/$G$38*G28,0) | I28: =IFERROR(G28-H28,0) | J28: =IFERROR(I28+(($I$6+$I$7)*I28/($I$38-($I$6+$I$7))),0) | K28: =IFERROR(J28/$I$38,0) | L28: =IFERROR($L$38*K28,0)
D29: Automatische creatie | G29: 0 | H29: =IFERROR($H$38/$G$38*G29,0) | I29: =IFERROR(G29-H29,0) | J29: =IFERROR(I29+(($I$6+$I$7)*I29/($I$38-($I$6+$I$7))),0) | K29: =IFERROR(J29/$I$38,0) | L29: =IFERROR($L$38*K29,0)
D30: Automatische creatie | G30: 0 | H30: =IFERROR($H$38/$G$38*G30,0) | I30: =IFERROR(G30-H30,0) | J30: =IFERROR(I30+(($I$6+$I$7)*I30/($I$38-($I$6+$I$7))),0) | K30: =IFERROR(J30/$I$38,0) | L30: =IFERROR($L$38*K30,0)
D31: Automatische creatie | G31: 0 | H31: =IFERROR($H$38/$G$38*G31,0) | I31: =IFERROR(G31-H31,0) | J31: =IFERROR(I31+(($I$6+$I$7)*I31/($I$38-($I$6+$I$7))),0) | K31: =IFERROR(J31/$I$38,0) | L31: =IFERROR($L$38*K31,0)
D32: Automatische creatie | G32: 0 | H32: =IFERROR($H$38/$G$38*G32,0) | I32: =IFERROR(G32-H32,0) | J32: =IFERROR(I32+(($I$6+$I$7)*I32/($I$38-($I$6+$I$7))),0) | K32: =IFERROR(J32/$I$38,0) | L32: =IFERROR($L$38*K32,0)
D33: Automatische creatie | G33: 0 | H33: =IFERROR($H$38/$G$38*G33,0) | I33: =IFERROR(G33-H33,0) | J33: =IFERROR(I33+(($I$6+$I$7)*I33/($I$38-($I$6+$I$7))),0) | K33: =IFERROR(J33/$I$38,0) | L33: =IFERROR($L$38*K33,0)
D34: Automatische creatie | G34: 0 | H34: =IFERROR($H$38/$G$38*G34,0) | I34: =IFERROR(G34-H34,0) | J34: =IFERROR(I34+(($I$6+$I$7)*I34/($I$38-($I$6+$I$7))),0) | K34: =IFERROR(J34/$I$38,0) | L34: =IFERROR($L$38*K34,0)
D35: Automatische creatie | G35: 0 | H35: =IFERROR($H$38/$G$38*G35,0) | I35: =IFERROR(G35-H35,0) | J35: =IFERROR(I35+(($I$6+$I$7)*I35/($I$38-($I$6+$I$7))),0) | K35: =IFERROR(J35/$I$38,0) | L35: =IFERROR($L$38*K35,0)
D36: Automatische creatie | G36: 0 | H36: =IFERROR($H$38/$G$38*G36,0) | I36: =IFERROR(G36-H36,0) | J36: =IFERROR(I36+(($I$6+$I$7)*I36/($I$38-($I$6+$I$7))),0) | K36: =IFERROR(J36/$I$38,0) | L36: =IFERROR($L$38*K36,0)
D37: Automatische creatie | G37: 0 | H37: =IFERROR($H$38/$G$38*G37,0) | I37: =IFERROR(G37-H37,0) | J37: =IFERROR(I37+(($I$6+$I$7)*I37/($I$38-($I$6+$I$7))),0) | K37: =IFERROR(J37/$I$38,0) | L37: =IFERROR($L$38*K37,0)
F38: =F6 | G38: =SUM(G6:G37) | H38: ='Costfile - Invoice discussion'!P102 | I38: =SUM(I6:I37) | J38: =SUM(J6:J37) | K38: =SUM(K6:K37) | L38: ='Costfile - Invoice discussion'!H105
A42: TD-standard Detailcodes
A43: 1xx | B43: Rebuild Project | F43: Instructions Technical department
A44: 00X | B44: Damage Claims | G44: * | H44: Enter heading (vessel, shipyard, purchase order and invoice number)
...

Sheet Scaffolding
M1: Last change | N1: =LastChange
B2: STAGING
F3: indication of Job? | J3: AREA | L3: AREA | M3: PRICE/M3 | N3: TOTAL
E4: =IF(C4="","",C4*D4) | N4: =IF(L4="","",L4*M4)
E5: =IF(C5="","",C5*D5) | N5: =IF(L5="","",L5*M5)
E6: =IF(C6="","",C6*D6) | N6: =IF(L6="","",L6*M6)
E7: =IF(C7="","",C7*D7) | N7: =IF(L7="","",L7*M7)
E8: =IF(C8="","",C8*D8) | N8: =IF(L8="","",L8*M8)
E9: =IF(C9="","",C9*D9) | N9: =IF(L9="","",L9*M9)
E10: =IF(C10="","",C10*D10) | N10: =IF(L10="","",L10*M10)
E11: =IF(C11="","",C11*D11) | N11: =IF(L11="","",L11*M11)
E12: =IF(C12="","",C12*D12) | N12: =IF(L12="","",L12*M12)
E13: =IF(C13="","",C13*D13) | N13: =IF(L13="","",L13*M13)
E14: =IF(C14="","",C14*D14) | N14: =IF(L14="","",L14*M14)
E15: =IF(C15="","",C15*D15) | N15: =IF(L15="","",L15*M15)
... E33: =IF(C33="","",C33*D33) | N33: =IF(L33="","",L33*M33)
N34: =SUM(N4:N33) | O34: =SUM(O4:O33)
B37: AGREED = | C37: =SUMIF($H$4:$H$33,"A",$N$4:$N$33) | D37: A
B38: DISCUSSION = | C38: =SUMIF($H$4:$H$33,"D",$N$4:$N$33) | D38: D
B39: NOT AGREED = | C39: =SUMIF($H$4:$H$33,"N",$N$4:$N$33) | D39: N

Sheet 3rd party Planner
A1: AL-IDRISI - Planner
A2: PLANNING | B2: Last change | C2: =LastChange
A3: % DONE
A4: TASK DONE | B4: Project Start Date | F4: Display Week | G4: 1 | K4: =IF($C$4="","","Week "&(K6-($C$4-WEEKDAY($C$4,1)+2))/7+1) | R4: =IF($C$4="","","Week "&(R6-($C$4-WEEKDAY($C$4,1)+2))/7+1) | Y4: =IF($C$4="","","Week "&(Y6-($C$4-WEEKDAY($C$4,1)+2))/7+1) | AF4: =IF($C$4="","","Week "&(AF6-($C$4-WEEKDAY($C$4,1)+2))/7+1) | AM4: =IF($C$4="","","Week "&(AM6-($C$4-WEEKDAY($C$4,1)+2))/7+1) | AT4: =IF($C$4="","","Week "&(AT6-($C$4-WEEKDAY($C$4,1)+2))/7+1) | BA4: =IF($C$4="","","Week "&(BA6-($C$4-WEEKDAY($C$4,1)+2))/7+1) | BH4: =IF($C$4="","","Week "&(BH6-($C$4-WEEKDAY($C$4,1)+2))/7+1)
A5: OVERDUE | B5: Current date | C5: =TODAY() | K5: =K6 | R5: =R6 | Y5: =Y6 | AF5: =AF6 | AM5: =AM6 | AT5: =AT6 | BA5: =BA6 | BH5: =BH6
K6: =IF($C$4="","",$C$4-WEEKDAY($C$4,1)+2+7*($G$4-1)) | L6: =IF(K6="","",K6+1) | M6: =IF(L6="","",L6+1) | N6: =IF(M6="","",M6+1) | O6: =IF(N6="","",N6+1) | P6: =IF(O6="","",O6+1) | Q6: =IF(P6="","",P6+1) | R6: =IF(Q6="","",Q6+1) | S6: =IF(R6="","",R6+1) | ... BN6: =IF(BM6="","",BM6+1)
B7: DESCRIPTION | C7: RESPONSIBLE | D7: PLANNED START | E7: PLANNED END | F7: % DONE | G7: WORK DAYS | H7: DATE DONE | I7: DAYS OVERDUE | K7: =IF(K6="","",CHOOSE(WEEKDAY(K6,1),"S","M","T","W","T","F","S")) | L7: =IF(L6="","",CHOOSE(WEEKDAY(L6,1),"S","M","T","W","T","F","S")) | M7: =IF(M6="","",CHOOSE(WEEKDAY(M6,1),"S","M","T","W","T","F","S")) | N7: =IF(N6="","",CHOOSE(WEEKDAY(N6,1),"S","M","T","W","T","F","S")) | O7: =IF(O6="","",CHOOSE(WEEKDAY(O6,1),"S","M","T","W","T","F","S")) | P7: =IF(P6="","",CHOOSE(WEEKDAY(P6,1),"S","M","T","W","T","F","S")) | Q7: =IF(Q6="","",CHOOSE(WEEKDAY(Q6,1),"S","M","T","W","T","F","S")) | R7: =IF(R6="","",CHOOSE(WEEKDAY(R6,1),"S","M","T","W","T","F","S")) | ... BN7: =IF(BN6="","",CHOOSE(WEEKDAY(BN6,1),"S","M","T","W","T","F","S"))
A8: =IF(ISERROR(VALUE(SUBSTITUTE(prevWBS,".",""))),"1",IF(ISERROR(FIND("`",SUBSTITUTE(prevWBS,".","`",1))),TEXT(VALUE(prevWBS)+1,"#"),TEXT(VALUE(LEFT(prevWBS,FIND("`",SUBSTITUTE(prevWBS,".","`",1))-1))+1,"#"))) | B8: Service engineers | G8: =IF(OR(E8=0,D8=0)," - ",NETWORKDAYS(D8,E8))
F9: =IF(D9="","",IF(D9="N/A","N/A",IF(($C$5-D9+1)/G9>1,1,IF(($C$5-D9+1)/G9<0,0,IF(OR(D9=0,$C$5=0),"-",($C$5-D9+1)/G9))))) | G9: =IF(D9="","",IF(D9="N/A","N/A",IF(OR(E9=0,D9=0)," - ",NETWORKDAYS(D9,E9)))) | I9: =IF(D9="","",IF(AND(H9="-",$C$5>E9),$C$5-E9,"-"))
F10: =IF(D10="","",IF(D10="N/A","N/A",IF(($C$5-D10+1)/G10>1,1,IF(($C$5-D10+1)/G10<0,0,IF(OR(D10=0,$C$5=0),"-",($C$5-D10+1)/G10))))) | G10: =IF(D10="","",IF(D10="N/A","N/A",IF(OR(E10=0,D10=0)," - ",NETWORKDAYS(D10,E10)))) | I10: =IF(D10="","",IF(AND(H10="-",$C$5>E10),$C$5-E10,"-"))
F11: =IF(D11="","",IF(D11="N/A","N/A",IF(($C$5-D11+1)/G11>1,1,IF(($C$5-D11+1)/G11<0,0,IF(OR(D11=0,$C$5=0),"-",($C$5-D11+1)/G11))))) | G11: =IF(D11="","",IF(D11="N/A","N/A",IF(OR(E11=0,D11=0)," - ",NETWORKDAYS(D11,E11)))) | I11: =IF(D11="","",IF(AND(H11="-",$C$5>E11),$C$5-E11,"-"))
F12: =IF(D12="","",IF(D12="N/A","N/A",IF(($C$5-D12+1)/G12>1,1,IF(($C$5-D12+1)/G12<0,0,IF(OR(D12=0,$C$5=0),"-",($C$5-D12+1)/G12))))) | G12: =IF(D12="","",IF(D12="N/A","N/A",IF(OR(E12=0,D12=0)," - ",NETWORKDAYS(D12,E12)))) | I12: =IF(D12="","",IF(AND(H12="-",$C$5>E12),$C$5-E12,"-"))
F13: =IF(D13="","",IF(D13="N/A","N/A",IF(($C$5-D13+1)/G13>1,1,IF(($C$5-D13+1)/G13<0,0,IF(OR(D13=0,$C$5=0),"-",($C$5-D13+1)/G13))))) | G13: =IF(D13="","",IF(D13="N/A","N/A",IF(OR(E13=0,D13=0)," - ",NETWORKDAYS(D13,E13)))) | I13: =IF(D13="","",IF(AND(H13="-",$C$5>E13),$C$5-E13,"-"))
F14: =IF(D14="","",IF(D14="N/A","N/A",IF(($C$5-D14+1)/G14>1,1,IF(($C$5-D14+1)/G14<0,0,IF(OR(D14=0,$C$5=0),"-",($C$5-D14+1)/G14))))) | G14: =IF(D14="","",IF(D14="N/A","N/A",IF(OR(E14=0,D14=0)," - ",NETWORKDAYS(D14,E14)))) | I14: =IF(D14="","",IF(AND(H14="-",$C$5>E14),$C$5-E14,"-"))
F15: =IF(D15="","",IF(D15="N/A","N/A",IF(($C$5-D15+1)/G15>1,1,IF(($C$5-D15+1)/G15<0,0,IF(OR(D15=0,$C$5=0),"-",($C$5-D15+1)/G15))))) | G15: =IF(D15="","",IF(D15="N/A","N/A",IF(OR(E15=0,D15=0)," - ",NETWORKDAYS(D15,E15)))) | I15: =IF(D15="","",IF(AND(H15="-",$C$5>E15),$C$5-E15,"-"))
F16: =IF(D16="","",IF(D16="N/A","N/A",IF(($C$5-D16+1)/G16>1,1,IF(($C$5-D16+1)/G16<0,0,IF(OR(D16=0,$C$5=0),"-",($C$5-D16+1)/G16))))) | G16: =IF(D16="","",IF(D16="N/A","N/A",IF(OR(E16=0,D16=0)," - ",NETWORKDAYS(D16,E16)))) | I16: =IF(D16="","",IF(AND(H16="-",$C$5>E16),$C$5-E16,"-"))
F17: =IF(D17="","",IF(D17="N/A","N/A",IF(($C$5-D17+1)/G17>1,1,IF(($C$5-D17+1)/G17<0,0,IF(OR(D17=0,$C$5=0),"-",($C$5-D17+1)/G17))))) | G17: =IF(D17="","",IF(D17="N/A","N/A",IF(OR(E17=0,D17=0)," - ",NETWORKDAYS(D17,E17)))) | I17: =IF(D17="","",IF(AND(H17="-",$C$5>E17),$C$5-E17,"-"))
F18: =IF(D18="","",IF(D18="N/A","N/A",IF(($C$5-D18+1)/G18>1,1,IF(($C$5-D18+1)/G18<0,0,IF(OR(D18=0,$C$5=0),"-",($C$5-D18+1)/G18))))) | G18: =IF(D18="","",IF(D18="N/A","N/A",IF(OR(E18=0,D18=0)," - ",NETWORKDAYS(D18,E18)))) | I18: =IF(D18="","",IF(AND(H18="-",$C$5>E18),$C$5-E18,"-"))
F19: =IF(D19="","",IF(D19="N/A","N/A",IF(($C$5-D19+1)/G19>1,1,IF(($C$5-D19+1)/G19<0,0,IF(OR(D19=0,$C$5=0),"-",($C$5-D19+1)/G19))))) | G19: =IF(D19="","",IF(D19="N/A","N/A",IF(OR(E19=0,D19=0)," - ",NETWORKDAYS(D19,E19)))) | I19: =IF(D19="","",IF(AND(H19="-",$C$5>E19),$C$5-E19,"-"))
F20: =IF(D20="","",IF(D20="N/A","N/A",IF(($C$5-D20+1)/G20>1,1,IF(($C$5-D20+1)/G20<0,0,IF(OR(D20=0,$C$5=0),"-",($C$5-D20+1)/G20))))) | G20: =IF(D20="","",IF(D20="N/A","N/A",IF(OR(E20=0,D20=0)," - ",NETWORKDAYS(D20,E20)))) | I20: =IF(D20="","",IF(AND(H20="-",$C$5>E20),$C$5-E20,"-"))
... F37: =IF(D37="","",IF(D37="N/A","N/A",IF(($C$5-D37+1)/G37>1,1,IF(($C$5-D37+1)/G37<0,0,IF(OR(D37=0,$C$5=0),"-",($C$5-D37+1)/G37))))) | G37: =IF(D37="","",IF(D37="N/A","N/A",IF(OR(E37=0,D37=0)," - ",NETWORKDAYS(D37,E37)))) | I37: =IF(D37="","",IF(AND(H37="-",$C$5>E37),$C$5-E37,"-"))

Sheet 3rd parties
A1: Service engineers file | M1: Rev. # | N1: Name | O1: Date
A2: 1) | B2: <VENDOR> (<SCOPE>) | M2: =IFERROR(LOOKUP(2,1/('SOW initial'!$G$3:$G$12<>""),'SOW initial'!$G$3:$G$12),"") | N2: =IFERROR(LOOKUP(2,1/('SOW initial'!$H$3:$H$12<>""),'SOW initial'!$H$3:$H$12),"") | O2: =IFERROR(LOOKUP(2,1/('SOW initial'!$I$3:$I$12<>""),'SOW initial'!$I$3:$I$12),"")
A3: no. | B3: description | C3: qty | D3: unit | E3: price/unit | F3: total price | G3: AVB | H3: PO | I3: DOCUMENTS | J3: Remarks | K3: ETCommence | L3: ETComplete | M3: Last change | O3: =LastChange
A4: 1 | B4: Air Travel
A5: 2 | B5: Hotel
A6: 3 | B6: Transport
A7: 4 | B7: Working time
B9: Total estimated cost | F9: =SUM(F4:F8)
A11: 2) | B11: <VENDOR> (<SCOPE>)
A12: no. | B12: description | C12: qty | D12: unit | E12: price/unit | F12: total price | G12: AVB | H12: PO | I12: DOCUMENTS | J12: Remarks | K12: ETCommence | L12: ETComplete
A13: 1 | B13: Air Travel
A14: 2 | B14: Hotel
A15: 3 | B15: Transport
A16: 4 | B16: Working time
B18: Total estimated cost | F18: =SUM(F13:F17)
A20: 3) | B20: <VENDOR> (<SCOPE>)
A21: no. | B21: description | C21: qty | D21: unit | E21: price/unit | F21: total price | G21: AVB | H21: PO | I21: DOCUMENTS | J21: Remarks | K21: ETCommence | L21: ETComplete
A22: 1 | B22: Air Travel
A23: 2 | B23: Hotel
A24: 3 | B24: Transport
A25: 4 | B25: Working time
B27: Total estimated cost | F27: =SUM(F22:F26)
A29: 4) | B29: <VENDOR> (<SCOPE>)
A30: no. | B30: description | C30: qty | D30: unit | E30: price/unit | F30: total price | G30: AVB | H30: PO | I30: DOCUMENTS | J30: Remarks | K30: ETCommence | L30: ETComplete
A31: 1 | B31: Air Travel
A32: 2 | B32: Hotel
A33: 3 | B33: Transport
A34: 4 | B34: Working time
B36: Total estimated cost | F36: =SUM(F31:F35)
A38: 5) | B38: <VENDOR> (<SCOPE>)
A39: no. | B39: description | C39: qty | D39: unit | E39: price/unit | F39: total price | G39: AVB | H39: PO | I39: DOCUMENTS | J39: Remarks | K39: ETCommence | L39: ETComplete
A40: 1 | B40: Air Travel
A41: 2 | B41: Hotel
A42: 3 | B42: Transport
A43: 4 | B43: Working time
B45: Total estimated cost | F45: =SUM(F40:F44)
A47: 6) | B47: <VENDOR> (<SCOPE>)
A48: no. | B48: description | C48: qty | D48: unit | E48: price/unit | F48: total price | G48: AVB | H48: PO | I48: DOCUMENTS | J48: Remarks | K48: ETCommence | L48: ETComplete
A49: 1 | B49: Air Travel
A50: 2 | B50: Hotel
...

Sheet SOW final
B2: AL-IDRISI - Drydock 2027 <Place> Actual scope of works | G2: Rev. # | H2: Name | I2: Date | K2: not yet started
G3: =IF('SOW initial'!G3="","",'SOW initial'!G3) | H3: =IF('SOW initial'!H3="","",'SOW initial'!H3) | I3: =IF('SOW initial'!I3="","",'SOW initial'!I3) | K3: Ongoing
G4: =IF('SOW initial'!G4="","",'SOW initial'!G4) | H4: =IF('SOW initial'!H4="","",'SOW initial'!H4) | I4: =IF('SOW initial'!I4="","",'SOW initial'!I4) | K4: Done
G5: =IF('SOW initial'!G5="","",'SOW initial'!G5) | H5: =IF('SOW initial'!H5="","",'SOW initial'!H5) | I5: =IF('SOW initial'!I5="","",'SOW initial'!I5) | K5: TBC
G6: =IF('SOW initial'!G6="","",'SOW initial'!G6) | H6: =IF('SOW initial'!H6="","",'SOW initial'!H6) | I6: =IF('SOW initial'!I6="","",'SOW initial'!I6) | K6: Cancelled
G7: =IF('SOW initial'!G7="","",'SOW initial'!G7) | H7: =IF('SOW initial'!H7="","",'SOW initial'!H7) | I7: =IF('SOW initial'!I7="","",'SOW initial'!I7)
G8: =IF('SOW initial'!G8="","",'SOW initial'!G8) | H8: =IF('SOW initial'!H8="","",'SOW initial'!H8) | I8: =IF('SOW initial'!I8="","",'SOW initial'!I8)
G9: =IF('SOW initial'!G9="","",'SOW initial'!G9) | H9: =IF('SOW initial'!H9="","",'SOW initial'!H9) | I9: =IF('SOW initial'!I9="","",'SOW initial'!I9)
G10: =IF('SOW initial'!G10="","",'SOW initial'!G10) | H10: =IF('SOW initial'!H10="","",'SOW initial'!H10) | I10: =IF('SOW initial'!I10="","",'SOW initial'!I10)
G11: =IF('SOW initial'!G11="","",'SOW initial'!G11) | H11: =IF('SOW initial'!H11="","",'SOW initial'!H11) | I11: =IF('SOW initial'!I11="","",'SOW initial'!I11)
G12: =IF('SOW initial'!G12="","",'SOW initial'!G12) | H12: =IF('SOW initial'!H12="","",'SOW initial'!H12) | I12: =IF('SOW initial'!I12="","",'SOW initial'!I12)
G13: Last change | I13: =LastChange
B15: Specs | C15: Description | D15: qty. | E15: unit | F15: Afloat/ Dock | G15: WL item | H15: RFQ | I15: PO | J15: Transport File | K15: Comments | L15: Remarks
B16: A. PILOTAGE, MOORING AND UNMOORING
B22: B. DRYDOCKING
B28: C. SERVICES
B34: D. GENERAL
B40: E. SURFACE PREPARATIONS
B46: F. PAINT
B52: G. STEEL
B58: H. TANKS
B64: I. SEAWATER LINES
B70: J. HOPPER
B76: M. PROPELLERS AND TAILSHAFTS
B82: N. ENGINES
... B100: X. MISCELLANEOUS

Sheet SOW initial
B2: AL-IDRISI - Drydock 2027 <Place> Estimated scope of works | G2: Rev. # | H2: Name | I2: Date | K2: not yet started
G3: Rev00 | H3: PSKO | I3: 46308 | K3: Ongoing
K4: Done
K5: TBC
K6: Cancelled
G13: Last change | I13: 46308
B15: Specs | C15: Description | D15: qty. | E15: unit | F15: Afloat/ Dock | G15: WL item | H15: RFQ | I15: PO | J15: Transport File | K15: Comments | L15: Remarks
B16: A. PILOTAGE, MOORING AND UNMOORING
B22: B. DRYDOCKING
B28: C. SERVICES
B34: D. GENERAL
B40: E. SURFACE PREPARATIONS
B46: F. PAINT
B52: G. STEEL
B58: H. TANKS
B64: I. SEAWATER LINES
B70: J. HOPPER
B76: M. PROPELLERS AND TAILSHAFTS
B82: N. ENGINES
... B100: X. MISCELLANEOUS

Sheet Budget file
A2: PRICE COMPARISON - DRYDOCKING AL-IDRISI | M2: Rev. # | N2: Name | O2: Date
A3: 1 <CUR> = | C3: Wisselkoers <date> | M3: =IFERROR(LOOKUP(2,1/('SOW initial'!$G$3:$G$12<>""),'SOW initial'!$G$3:$G$12),"") | N3: =IFERROR(LOOKUP(2,1/('SOW initial'!$H$3:$H$12<>""),'SOW initial'!$H$3:$H$12),"") | O3: =IFERROR(LOOKUP(2,1/('SOW initial'!$I$3:$I$12<>""),'SOW initial'!$I$3:$I$12),"")
A4: 1 USD = | M4: Last change | O4: =LastChange
A5: 1 USD =
E6: Yard 1 | G6: Draft Invoice | H6: Draft Invoice | I6: Agreed | J6: Not agreed | K6: Discussion | L6: Obtained reduction | M6: Final Invoice | N6: Remarks | O6: Cost Code
A7: Par. | B7: Description | C7: Units | D7: Qty. | E7: USD/unit | F7: USD | I7: USD | J7: USD | K7: USD | L7: USD | M7: USD
F8: =D8*E8
F9: =D9*E9
F10: =D10*E10
F11: =D11*E11
F12: =D12*E12
B13: Subtotal Pilotage, mooring and unmooring | F13: =SUBTOTAL(9,F8:F12) | G13: =SUBTOTAL(9,G8:G12) | H13: =SUBTOTAL(9,H8:H12) | I13: =SUBTOTAL(9,I8:I12) | J13: =SUBTOTAL(9,J8:J12) | K13: =SUBTOTAL(9,K8:K12) | L13: =SUBTOTAL(9,L8:L12) | M13: =SUBTOTAL(9,M8:M12)
F14: =D14*E14
F15: =D15*E15
F16: =D16*E16
F17: =D17*E17
F18: =D18*E18
B19: Subtotal Drydocking | F19: =SUBTOTAL(9,F14:F18) | G19: =SUBTOTAL(9,G14:G18) | H19: =SUBTOTAL(9,H14:H18) | I19: =SUBTOTAL(9,I14:I18) | J19: =SUBTOTAL(9,J14:J18) | K19: =SUBTOTAL(9,K14:K18) | L19: =SUBTOTAL(9,L14:L18) | M19: =SUBTOTAL(9,M14:M18)
F20: =D20*E20
F21: =D21*E21
F22: =D22*E22
F23: =D23*E23
F24: =D24*E24
B25: Subtotal Services | F25: =SUBTOTAL(9,F20:F24) | G25: =SUBTOTAL(9,G20:G24) | H25: =SUBTOTAL(9,H20:H24) | I25: =SUBTOTAL(9,I20:I24) | J25: =SUBTOTAL(9,J20:J24) | K25: =SUBTOTAL(9,K20:K24) | L25: =SUBTOTAL(9,L20:L24) | M25: =SUBTOTAL(9,M20:M24)
F26: =D26*E26
F27: =D27*E27
F28: =D28*E28
F29: =D29*E29
F30: =D30*E30
B31: Subtotal General | F31: =SUBTOTAL(9,F26:F30) | G31: =SUBTOTAL(9,G26:G30) | H31: =SUBTOTAL(9,H26:H30) | I31: =SUBTOTAL(9,I26:I30) | J31: =SUBTOTAL(9,J26:J30) | K31: =SUBTOTAL(9,K26:K30) | L31: =SUBTOTAL(9,L26:L30) | M31: =SUBTOTAL(9,M26:M30)
F32: =D32*E32
F33: =D33*E33
F34: =D34*E34
F35: =D35*E35
F36: =D36*E36
B37: Subtotal Surface preparations | F37: =SUBTOTAL(9,F32:F36) | G37: =SUBTOTAL(9,G32:G36) | H37: =SUBTOTAL(9,H32:H36) | I37: =SUBTOTAL(9,I32:I36) | J37: =SUBTOTAL(9,J32:J36) | K37: =SUBTOTAL(9,K32:K36) | L37: =SUBTOTAL(9,L32:L36) | M37: =SUBTOTAL(9,M32:M36)
F38: =D38*E38
F39: =D39*E39
F40: =D40*E40
F41: =D41*E41
...
